java.lang.RuntimeException: An error occured while executing doInBackground()
	at com.qihoo.jiagu.g.b.b.done(lo:294)
	at java.util.concurrent.FutureTask.finishCompletion(FutureTask.java:384)
	at java.util.concurrent.FutureTask.setException(FutureTask.java:251)
	at java.util.concurrent.FutureTask.run(FutureTask.java:271)
	at com.qihoo.jiagu.g.b.h.run(dp:168)
	at java.util.concurrent.ThreadPoolExecutor.runWorker(ThreadPoolExecutor.java:1142)
	at java.util.concurrent.ThreadPoolExecutor$Worker.run(ThreadPoolExecutor.java:617)
	at java.lang.Thread.run(Thread.java:745)
Caused by: java.lang.NullPointerException
	at com.qihoo.jiagu.f.j.ALLATORIxDEMO(ae:544)
	at com.qihoo.jiagu.h.J.ALLATORIxDEMO(tr:24)
	at com.qihoo.jiagu.h.J.ALLATORIxDEMO(tr:209)
	at com.qihoo.jiagu.e.e.m.ALLATORIxDEMO(sm:4)
	at com.qihoo.jiagu.g.a.a.K(dl:188)
	at com.qihoo.jiagu.g.b.L.ALLATORIxDEMO(lo:296)
	at com.qihoo.jiagu.g.a.a.ALLATORIxDEMO(dl:260)
	at com.qihoo.jiagu.g.a.a.ALLATORIxDEMO(dl:121)
	at com.qihoo.jiagu.g.b.g.call(lo:195)
	at java.util.concurrent.FutureTask.run(FutureTask.java:266)
	... 4 more
java.lang.NullPointerException
	at com.qihoo.jiagu.f.j.ALLATORIxDEMO(ae:544)
	at com.qihoo.jiagu.h.J.ALLATORIxDEMO(tr:24)
	at com.qihoo.jiagu.h.J.ALLATORIxDEMO(tr:209)
	at com.qihoo.jiagu.e.e.m.ALLATORIxDEMO(sm:4)
	at com.qihoo.jiagu.g.a.a.K(dl:188)
	at com.qihoo.jiagu.g.b.L.ALLATORIxDEMO(lo:296)
	at com.qihoo.jiagu.g.a.a.ALLATORIxDEMO(dl:260)
	at com.qihoo.jiagu.g.a.a.ALLATORIxDEMO(dl:121)
	at com.qihoo.jiagu.g.b.g.call(lo:195)
	at java.util.concurrent.FutureTask.run(FutureTask.java:266)
	at com.qihoo.jiagu.g.b.h.run(dp:168)
	at java.util.concurrent.ThreadPoolExecutor.runWorker(ThreadPoolExecutor.java:1142)
	at java.util.concurrent.ThreadPoolExecutor$Worker.run(ThreadPoolExecutor.java:617)
	at java.lang.Thread.run(Thread.java:745)
